Workbook

Sheet Data
A1: Folder Name | B1: Image Name | C1: Image file format | D1: Pixel Size (µm) | E1: Sample Name | F1: Material | G1: Surface Condition | H1: Machine | I1: Track No. | J1: Scan Direction | K1: Est. Spot Diameter (D4σ = Dg) | L1: Laser Power (W) | M1: Laser Scan Speed (mm/s) | N1: Width (µm) | O1: Depth (µm)
A2: IN718_20210323_M290 | B2: Snap-121 | C2: .tiff | D2: 0.155 | E2: 03-23-2021 IN718 Bare Plate | F2: IN718 | G2: 320 grit | H2: EOS M290 | I2: N/A | J2: X | K2: 80 | L2: 285 | M2: 960 | N2: 142.83 | O2: 125.719
A3: IN718_20210323_M290 | B3: Snap-122 | C3: .tiff | D3: 0.155 | E3: 03-23-2021 IN718 Bare Plate | F3: IN718 | G3: 320 grit | H3: EOS M290 | I3: N/A | J3: X | K3: 80 | L3: 285 | M3: 960 | N3: 141.433 | O3: 120.83
A4: IN718_20210323_M290 | B4: Snap-123 | C4: .tiff | D4: 0.155 | E4: 03-23-2021 IN718 Bare Plate | F4: IN718 | G4: 320 grit | H4: EOS M290 | I4: N/A | J4: X | K4: 80 | L4: 285 | M4: 960 | N4: 141.084 | O4: 121.877
A5: IN718_20210323_M290 | B5: Snap-124 | C5: .tiff | D5: 0.155 | E5: 03-23-2021 IN718 Bare Plate | F5: IN718 | G5: 320 grit | H5: EOS M290 | I5: N/A | J5: X | K5: 80 | L5: 285 | M5: 960 | N5: 140.386 | O5: 122.925
A6: IN718_20210323_M290 | B6: Snap-125 | C6: .tiff | D6: 0.155 | E6: 03-23-2021 IN718 Bare Plate | F6: IN718 | G6: 320 grit | H6: EOS M290 | I6: N/A | J6: X | K6: 80 | L6: 285 | M6: 960 | N6: 140.037 | O6: 123.74
A7: IN718_20210323_M290 | B7: Snap-126 | C7: .tiff | D7: 0.155 | E7: 03-23-2021 IN718 Bare Plate | F7: IN718 | G7: 320 grit | H7: EOS M290 | I7: N/A | J7: X | K7: 80 | L7: 285 | M7: 960 | N7: 135.846 | O7: 121.528
A8: IN718_20210323_M290 | B8: Snap-127 | C8: .tiff | D8: 0.155 | E8: 03-23-2021 IN718 Bare Plate | F8: IN718 | G8: 320 grit | H8: EOS M290 | I8: N/A | J8: X | K8: 80 | L8: 285 | M8: 960 | N8: 141.783 | O8: 119.782
A9: IN718_20210323_M290 | B9: Snap-128 | C9: .tiff | D9: 0.155 | E9: 03-23-2021 IN718 Bare Plate | F9: IN718 | G9: 320 grit | H9: EOS M290 | I9: N/A | J9: X | K9: 80 | L9: 285 | M9: 960 | N9: 145.624 | O9: 125.369
A10: IN718_20210323_M290 | B10: Snap-129 | C10: .tiff | D10: 0.155 | E10: 03-23-2021 IN718 Bare Plate | F10: IN718 | G10: 320 grit | H10: EOS M290 | I10: N/A | J10: X | K10: 80 | L10: 285 | M10: 960 | N10: 143.529 | O10: 120.131
A11: IN718_20210323_M290 | B11: Snap-121 | C11: .tiff | D11: 0.155 | E11: 03-23-2021 IN718 Bare Plate | F11: IN718 | G11: 320 grit | H11: EOS M290 | I11: N/A | J11: X | K11: 80 | L11: 285 | M11: 960 | N11: 147.021 | O11: 124.322
A12: IN718_20210323_M290 | B12: Snap-122 | C12: .tiff | D12: 0.155 | E12: 03-23-2021 IN718 Bare Plate | F12: IN718 | G12: 320 grit | H12: EOS M290 | I12: N/A | J12: X | K12: 80 | L12: 285 | M12: 960 | N12: 139.687 | O12: 122.925
A13: IN718_20210323_M290 | B13: Snap-123 | C13: .tiff | D13: 0.155 | E13: 03-23-2021 IN718 Bare Plate | F13: IN718 | G13: 320 grit | H13: EOS M290 | I13: N/A | J13: X | K13: 80 | L13: 285 | M13: 960 | N13: 141.433 | O13: 117.337
... A19: IN718_20210323_M290 | B19: Snap-129 | C19: .tiff | D19: 0.155 | E19: 03-23-2021 IN718 Bare Plate | F19: IN718 | G19: 320 grit | H19: EOS M290 | I19: N/A | J19: X | K19: 80 | L19: 285 | M19: 960 | N19: 142.83 | O19: 122.226
A20: IN718_20210713_AMB_X | B20: 2021-07-13_AMB_X_01_scalebar | C20: .tiff | D20: 0.93 | E20: 2021-07-13-AMB_X | F20: IN718 | G20: 320 grit | H20: AMMT | I20: 1 | J20: X | K20: 63.167443 | L20: 285 | M20: 960 | N20: 137.544 | O20: 143.782
A21: IN718_20210713_AMB_X | B21: 2021-07-13_AMB_X_01_scalebar | C21: .tiff | D21: 0.93 | E21: 2021-07-13-AMB_X | F21: IN718 | G21: 320 grit | H21: AMMT | I21: 1 | J21: X | K21: 63.167443 | L21: 285 | M21: 960 | N21: 138.888 | O21: 140.971
A22: IN718_20210713_AMB_X | B22: 2021-07-13_AMB_X_02_scalebar | C22: .tiff | D22: 0.93 | E22: 2021-07-13-AMB_X | F22: IN718 | G22: 320 grit | H22: AMMT | I22: 2 | J22: X | K22: 63.167443 | L22: 285 | M22: 960 | N22: 133.735 | O22: 146.078
A23: IN718_20210713_AMB_X | B23: 2021-07-13_AMB_X_02_scalebar | C23: .tiff | D23: 0.93 | E23: 2021-07-13-AMB_X | F23: IN718 | G23: 320 grit | H23: AMMT | I23: 2 | J23: X | K23: 63.167443 | L23: 285 | M23: 960 | N23: 128.987 | O23: 140.577
A24: IN718_20210713_AMB_X | B24: 2021-07-13_AMB_X_03_scalebar | C24: .tiff | D24: 0.93 | E24: 2021-07-13-AMB_X | F24: IN718 | G24: 320 grit | H24: AMMT | I24: 3 | J24: X | K24: 63.167443 | L24: 285 | M24: 960 | N24: 144.675 | O24: 147.568
A25: IN718_20210713_AMB_X | B25: 2021-07-13_AMB_X_03_scalebar | C25: .tiff | D25: 0.93 | E25: 2021-07-13-AMB_X | F25: IN718 | G25: 320 grit | H25: AMMT | I25: 3 | J25: X | K25: 63.167443 | L25: 285 | M25: 960 | N25: 143.59 | O25: 146.121
A26: IN718_20210713_AMB_X | B26: 2021-07-13_AMB_X_04_scalebar | C26: .tiff | D26: 0.93 | E26: 2021-07-13-AMB_X | F26: IN718 | G26: 320 grit | H26: AMMT | I26: 4 | J26: X | K26: 70.09812 | L26: 285 | M26: 960 | N26: 146.295 | O26: 125.925
A27: IN718_20210713_AMB_X | B27: 2021-07-13_AMB_X_04_scalebar | C27: .tiff | D27: 0.93 | E27: 2021-07-13-AMB_X | F27: IN718 | G27: 320 grit | H27: AMMT | I27: 4 | J27: X | K27: 70.09812 | L27: 285 | M27: 960 | N27: 142.591 | O27: 124.767
A28: IN718_20210713_AMB_X | B28: 2021-07-13_AMB_X_05_scalebar | C28: .tiff | D28: 0.93 | E28: 2021-07-13-AMB_X | F28: IN718 | G28: 320 grit | H28: AMMT | I28: 5 | J28: X | K28: 70.09812 | L28: 285 | M28: 960 | N28: 130.007 | O28: 131.249
A29: IN718_20210713_AMB_X | B29: 2021-07-13_AMB_X_05_scalebar | C29: .tiff | D29: 0.93 | E29: 2021-07-13-AMB_X | F29: IN718 | G29: 320 grit | H29: AMMT | I29: 5 | J29: X | K29: 70.09812 | L29: 285 | M29: 960 | N29: 128.147 | O29: 135.739
A30: IN718_20210713_AMB_X | B30: 2021-07-13_AMB_X_06_scalebar | C30: .tiff | D30: 0.93 | E30: 2021-07-13-AMB_X | F30: IN718 | G30: 320 grit | H30: AMMT | I30: 6 | J30: X | K30: 70.09812 | L30: 285 | M30: 960 | N30: 131.979 | O30: 133.969
A31: IN718_20210713_AMB_X | B31: 2021-07-13_AMB_X_06_scalebar | C31: .tiff | D31: 0.93 | E31: 2021-07-13-AMB_X | F31: IN718 | G31: 320 grit | H31: AMMT | I31: 6 | J31: X | K31: 70.09812 | L31: 285 | M31: 960 | N31: 128.332 | O31: 136.851
... A55: IN718_20210713_AMB_X | B55: 2021-07-13_AMB_X_18_scalebar | C55: .tiff | D55: 0.93 | E55: 2021-07-13-AMB_X | F55: IN718 | G55: 320 grit | H55: AMMT | I55: 18 | J55: X | K55: 74.34128 | L55: 285 | M55: 960 | N55: 136.187 | O55: 137.021
A56: IN718_20210713_AMB_Y | B56: 2021-07-13_AMB_Y_MB_01_scalebar | C56: .tiff | D56: 0.93 | E56: 2021-07-13-AMB_Y | F56: IN718 | G56: 320 grit | H56: AMMT | I56: B1 | J56: +Y | K56: 63.167443 | L56: 285 | M56: 960 | N56: 133.571 | O56: 176.766
A57: IN718_20210713_AMB_Y | B57: 2021-07-13_AMB_Y_MB_02_scalebar | C57: .tiff | D57: 0.93 | E57: 2021-07-13-AMB_Y | F57: IN718 | G57: 320 grit | H57: AMMT | I57: B2 | J57: +Y | K57: 63.167443 | L57: 285 | M57: 960 | N57: 126.308 | O57: 178.723
A58: IN718_20210713_AMB_Y | B58: 2021-07-13_AMB_Y_MB_05_scalebar | C58: .tiff | D58: 0.93 | E58: 2021-07-13-AMB_Y | F58: IN718 | G58: 320 grit | H58: AMMT | I58: B5 | J58: +Y | K58: 55.93108 | L58: 285 | M58: 960 | N58: 117.223 | O58: 200.423
A59: IN718_20210713_AMB_Y | B59: 2021-07-13_AMB_Y_MB_06_scalebar | C59: .tiff | D59: 0.93 | E59: 2021-07-13-AMB_Y | F59: IN718 | G59: 320 grit | H59: AMMT | I59: B6 | J59: +Y | K59: 55.93108 | L59: 285 | M59: 960 | N59: 117.954 | O59: 199.027
A60: IN718_20210713_AMB_Y | B60: 2021-07-13_AMB_Y_MB_09_scalebar | C60: .tiff | D60: 0.93 | E60: 2021-07-13-AMB_Y | F60: IN718 | G60: 320 grit | H60: AMMT | I60: B9 | J60: +Y | K60: 74.34128 | L60: 285 | M60: 960 | N60: 145.865 | O60: 144.785
A61: IN718_20210713_AMB_Y | B61: 2021-07-13_AMB_Y_MB_10_scalebar | C61: .tiff | D61: 0.93 | E61: 2021-07-13-AMB_Y | F61: IN718 | G61: 320 grit | H61: AMMT | I61: B10 | J61: +Y | K61: 74.34128 | L61: 285 | M61: 960 | N61: 143.805 | O61: 144.336
A62: IN718_20210713_AMB_Y | B62: 2021-07-13_AMB_Y_MB_01_scalebar | C62: .tiff | D62: 0.93 | E62: 2021-07-13-AMB_Y | F62: IN718 | G62: 320 grit | H62: AMMT | I62: M1 | J62: +Y | K62: 63.167443 | L62: 285 | M62: 960 | N62: 135.232 | O62: 176.433
A63: IN718_20210713_AMB_Y | B63: 2021-07-13_AMB_Y_MB_02_scalebar | C63: .tiff | D63: 0.93 | E63: 2021-07-13-AMB_Y | F63: IN718 | G63: 320 grit | H63: AMMT | I63: M2 | J63: +Y | K63: 63.167443 | L63: 285 | M63: 960 | N63: 128.919 | O63: 179.091
A64: IN718_20210713_AMB_Y | B64: 2021-07-13_AMB_Y_MB_05_scalebar | C64: .tiff | D64: 0.93 | E64: 2021-07-13-AMB_Y | F64: IN718 | G64: 320 grit | H64: AMMT | I64: M5 | J64: +Y | K64: 55.93108 | L64: 285 | M64: 960 | N64: 113.74 | O64: 199.965
A65: IN718_20210713_AMB_Y | B65: 2021-07-13_AMB_Y_MB_06_scalebar | C65: .tiff | D65: 0.93 | E65: 2021-07-13-AMB_Y | F65: IN718 | G65: 320 grit | H65: AMMT | I65: M6 | J65: +Y | K65: 55.93108 | L65: 285 | M65: 960 | N65: 113.036 | O65: 203.154
A66: IN718_20210713_AMB_Y | B66: 2021-07-13_AMB_Y_MB_09_scalebar | C66: .tiff | D66: 0.93 | E66: 2021-07-13-AMB_Y | F66: IN718 | G66: 320 grit | H66: AMMT | I66: M9 | J66: +Y | K66: 74.34128 | L66: 285 | M66: 960 | N66: 149.068 | O66: 142.05
A67: IN718_20210713_AMB_Y | B67: 2021-07-13_AMB_Y_MB_10_scalebar | C67: .tiff | D67: 0.93 | E67: 2021-07-13-AMB_Y | F67: IN718 | G67: 320 grit | H67: AMMT | I67: M10 | J67: +Y | K67: 74.34128 | L67: 285 | M67: 960 | N67: 143.539 | O67: 141.412
... A73: IN718_20210713_AMB_Y | B73: 2021-07-13_AMB_Y_T_10_scalebar | C73: .tiff | D73: 0.93 | E73: 2021-07-13-AMB_Y | F73: IN718 | G73: 320 grit | H73: AMMT | I73: T10 | J73: +Y | K73: 74.34128 | L73: 285 | M73: 960 | N73: 147.373 | O73: 147.6
...

Sheet Summary
A1: Material | B1: Machine | C1: Estimated D4σ Spot Diameter (µm) | D1: Laser Power (W) | E1: Scan Speed (mm/s) | F1: no. of measurements | G1: t-value (p = 1- 0.68/2 ) | H1: Optical resolution (µm) | I1: User selection (µm) | J1: Average Width (µm) | K1: Std. dev. Width (µm) | L1: Standard uncertainty of the mean width (µm) | M1: Width: Variability along track (µm) | N1: Width: Combined, Expanded uncertainty (µm); U (k=2) | O1: Average Depth (µm) | P1: Std. dev. Depth (µm) | Q1: Standard uncertainty of the mean depth (µm) | R1: Depth: Variability along track (µm) | S1: Depth: Combined, Expanded uncertainty (µm); U (k-2)
A2: IN718 | B2: EOS M290 | C2: 80 | D2: 285 | E2: 960 | F2: {=COUNT(IF((Data!$F$2:$F$251=$A2)*(Data!$H$2:$H$251=$B2)*(Data!$K$2:$K$251=$C2)*(Data!$L$2:$L$251=$D2)*(Data!$M$2:$M$251=$E2),Data!$N$2:$N$251," " ))} -> 18 | G2: 1.0244 | H2: 0.5 | I2: =2*Data!D2 -> 0.31 | J2: {=AVERAGE(IF((Data!$F$2:$F$251=$A2)*(Data!$H$2:$H$251=$B2)*(Data!$K$2:$K$251=$C2)*(Data!$L$2:$L$251=$D2)*(Data!$M$2:$M$251=$E2),Data!$N$2:$N$251," " ))} -> 141.33639 | K2: {=STDEV(IF((Data!$F$2:$F$251=$A2)*(Data!$H$2:$H$251=$B2)*(Data!$K$2:$K$251=$C2)*(Data!$L$2:$L$251=$D2)*(Data!$M$2:$M$251=$E2),Data!$N$2:$N$251," " ))} -> 2.7230069 | L2: =G2*K2/SQRT(F2) -> 0.65747927 | M2: =J2*2% -> 2.8267278 | N2: =2*SQRT(SUMSQ(H2,I2,L2,M2)) -> 5.9224214 | O2: {=AVERAGE(IF((Data!$F$2:$F$251=$A2)*(Data!$H$2:$H$251=$B2)*(Data!$K$2:$K$251=$C2)*(Data!$L$2:$L$251=$D2)*(Data!$M$2:$M$251=$E2),Data!$O$2:$O$251," " ))} -> 122.38811 | P2: {=STDEV(IF((Data!$F$2:$F$251=$A2)*(Data!$H$2:$H$251=$B2)*(Data!$K$2:$K$251=$C2)*(Data!$L$2:$L$251=$D2)*(Data!$M$2:$M$251=$E2),Data!$O$2:$O$251," " ))} -> 2.0901071 | Q2: =G2*P2/SQRT(F2) -> 0.50466345 | R2: =O2*5% -> 6.1194056 | S2: =2*SQRT(SUMSQ(H2,I2,Q2,R2)) -> 12.336598
A3: IN718 | B3: AMMT | C3: 63.167443 | D3: 285 | E3: 960 | F3: {=COUNT(IF((Data!$F$2:$F$251=$A3)*(Data!$H$2:$H$251=$B3)*(Data!$K$2:$K$251=$C3)*(Data!$L$2:$L$251=$D3)*(Data!$M$2:$M$251=$E3),Data!$N$2:$N$251," " ))} -> 12 | G3: 1.0415 | H3: 0.5 | I3: =2*Data!D3 -> 0.31 | J3: {=AVERAGE(IF((Data!$F$2:$F$251=$A3)*(Data!$H$2:$H$251=$B3)*(Data!$K$2:$K$251=$C3)*(Data!$L$2:$L$251=$D3)*(Data!$M$2:$M$251=$E3),Data!$N$2:$N$251," " ))} -> 133.30492 | K3: {=STDEV(IF((Data!$F$2:$F$251=$A3)*(Data!$H$2:$H$251=$B3)*(Data!$K$2:$K$251=$C3)*(Data!$L$2:$L$251=$D3)*(Data!$M$2:$M$251=$E3),Data!$N$2:$N$251," " ))} -> 7.0344609 | L3: =G3*K3/SQRT(F3) -> 2.1149469 | M3: =J3*2% -> 2.6660983 | N3: =2*SQRT(SUMSQ(H3,I3,L3,M3)) -> 6.9071502 | O3: {=AVERAGE(IF((Data!$F$2:$F$251=$A3)*(Data!$H$2:$H$251=$B3)*(Data!$K$2:$K$251=$C3)*(Data!$L$2:$L$251=$D3)*(Data!$M$2:$M$251=$E3),Data!$O$2:$O$251," " ))} -> 161.22542 | P3: {=STDEV(IF((Data!$F$2:$F$251=$A3)*(Data!$H$2:$H$251=$B3)*(Data!$K$2:$K$251=$C3)*(Data!$L$2:$L$251=$D3)*(Data!$M$2:$M$251=$E3),Data!$O$2:$O$251," " ))} -> 17.931003 | Q3: =G3*P3/SQRT(F3) -> 5.3910485 | R3: =O3*5% -> 8.0612708 | S3: =2*SQRT(SUMSQ(H3,I3,Q3,R3)) -> 19.431273
A4: IN718 | B4: AMMT | C4: 70.09812 | D4: 285 | E4: 960 | F4: {=COUNT(IF((Data!$F$2:$F$251=$A4)*(Data!$H$2:$H$251=$B4)*(Data!$K$2:$K$251=$C4)*(Data!$L$2:$L$251=$D4)*(Data!$M$2:$M$251=$E4),Data!$N$2:$N$251," " ))} -> 6 | G4: 1.1037 | H4: 0.5 | I4: =2*Data!D4 -> 0.31 | J4: {=AVERAGE(IF((Data!$F$2:$F$251=$A4)*(Data!$H$2:$H$251=$B4)*(Data!$K$2:$K$251=$C4)*(Data!$L$2:$L$251=$D4)*(Data!$M$2:$M$251=$E4),Data!$N$2:$N$251," " ))} -> 134.5585 | K4: {=STDEV(IF((Data!$F$2:$F$251=$A4)*(Data!$H$2:$H$251=$B4)*(Data!$K$2:$K$251=$C4)*(Data!$L$2:$L$251=$D4)*(Data!$M$2:$M$251=$E4),Data!$N$2:$N$251," " ))} -> 7.8678218 | L4: =G4*K4/SQRT(F4) -> 3.5451117 | M4: =J4*2% -> 2.69117 | N4: =2*SQRT(SUMSQ(H4,I4,L4,M4)) -> 8.9791566 | O4: {=AVERAGE(IF((Data!$F$2:$F$251=$A4)*(Data!$H$2:$H$251=$B4)*(Data!$K$2:$K$251=$C4)*(Data!$L$2:$L$251=$D4)*(Data!$M$2:$M$251=$E4),Data!$O$2:$O$251," " ))} -> 131.41667 | P4: {=STDEV(IF((Data!$F$2:$F$251=$A4)*(Data!$H$2:$H$251=$B4)*(Data!$K$2:$K$251=$C4)*(Data!$L$2:$L$251=$D4)*(Data!$M$2:$M$251=$E4),Data!$O$2:$O$251," " ))} -> 5.0819983 | Q4: =G4*P4/SQRT(F4) -> 2.2898653 | R4: =O4*5% -> 6.5708333 | S4: =2*SQRT(SUMSQ(H4,I4,Q4,R4)) -> 13.96645
A5: IN718 | B5: AMMT | C5: 59.052 | D5: 285 | E5: 960 | F5: {=COUNT(IF((Data!$F$2:$F$251=$A5)*(Data!$H$2:$H$251=$B5)*(Data!$K$2:$K$251=$C5)*(Data!$L$2:$L$251=$D5)*(Data!$M$2:$M$251=$E5),Data!$N$2:$N$251," " ))} -> 6 | G5: 1.1037 | H5: 0.5 | I5: =2*Data!D5 -> 0.31 | J5: {=AVERAGE(IF((Data!$F$2:$F$251=$A5)*(Data!$H$2:$H$251=$B5)*(Data!$K$2:$K$251=$C5)*(Data!$L$2:$L$251=$D5)*(Data!$M$2:$M$251=$E5),Data!$N$2:$N$251," " ))} -> 123.81767 | K5: {=STDEV(IF((Data!$F$2:$F$251=$A5)*(Data!$H$2:$H$251=$B5)*(Data!$K$2:$K$251=$C5)*(Data!$L$2:$L$251=$D5)*(Data!$M$2:$M$251=$E5),Data!$N$2:$N$251," " ))} -> 3.3102314 | L5: =G5*K5/SQRT(F5) -> 1.4915361 | M5: =J5*2% -> 2.4763533 | N5: =2*SQRT(SUMSQ(H5,I5,L5,M5)) -> 5.9002053 | O5: {=AVERAGE(IF((Data!$F$2:$F$251=$A5)*(Data!$H$2:$H$251=$B5)*(Data!$K$2:$K$251=$C5)*(Data!$L$2:$L$251=$D5)*(Data!$M$2:$M$251=$E5),Data!$O$2:$O$251," " ))} -> 177.4925 | P5: {=STDEV(IF((Data!$F$2:$F$251=$A5)*(Data!$H$2:$H$251=$B5)*(Data!$K$2:$K$251=$C5)*(Data!$L$2:$L$251=$D5)*(Data!$M$2:$M$251=$E5),Data!$O$2:$O$251," " ))} -> 5.5479645 | Q5: =G5*P5/SQRT(F5) -> 2.499822 | R5: =O5*5% -> 8.874625 | S5: =2*SQRT(SUMSQ(H5,I5,Q5,R5)) -> 18.477465
A6: IN718 | B6: AMMT | C6: 48.25168 | D6: 285 | E6: 960 | F6: {=COUNT(IF((Data!$F$2:$F$251=$A6)*(Data!$H$2:$H$251=$B6)*(Data!$K$2:$K$251=$C6)*(Data!$L$2:$L$251=$D6)*(Data!$M$2:$M$251=$E6),Data!$N$2:$N$251," " ))} -> 6 | G6: 1.1037 | H6: 0.5 | I6: =2*Data!D6 -> 0.31 | J6: {=AVERAGE(IF((Data!$F$2:$F$251=$A6)*(Data!$H$2:$H$251=$B6)*(Data!$K$2:$K$251=$C6)*(Data!$L$2:$L$251=$D6)*(Data!$M$2:$M$251=$E6),Data!$N$2:$N$251," " ))} -> 111.65183 | K6: {=STDEV(IF((Data!$F$2:$F$251=$A6)*(Data!$H$2:$H$251=$B6)*(Data!$K$2:$K$251=$C6)*(Data!$L$2:$L$251=$D6)*(Data!$M$2:$M$251=$E6),Data!$N$2:$N$251," " ))} -> 2.789299 | L6: =G6*K6/SQRT(F6) -> 1.2568125 | M6: =J6*2% -> 2.2330367 | N6: =2*SQRT(SUMSQ(H6,I6,L6,M6)) -> 5.2581862 | O6: {=AVERAGE(IF((Data!$F$2:$F$251=$A6)*(Data!$H$2:$H$251=$B6)*(Data!$K$2:$K$251=$C6)*(Data!$L$2:$L$251=$D6)*(Data!$M$2:$M$251=$E6),Data!$O$2:$O$251," " ))} -> 244.88783 | P6: {=STDEV(IF((Data!$F$2:$F$251=$A6)*(Data!$H$2:$H$251=$B6)*(Data!$K$2:$K$251=$C6)*(Data!$L$2:$L$251=$D6)*(Data!$M$2:$M$251=$E6),Data!$O$2:$O$251," " ))} -> 2.6160048 | Q6: =G6*P6/SQRT(F6) -> 1.178729 | R6: =O6*5% -> 12.244392 | S6: =2*SQRT(SUMSQ(H6,I6,Q6,R6)) -> 24.630114
A7: IN718 | B7: AMMT | C7: 74.34128 | D7: 285 | E7: 960 | F7: {=COUNT(IF((Data!$F$2:$F$251=$A7)*(Data!$H$2:$H$251=$B7)*(Data!$K$2:$K$251=$C7)*(Data!$L$2:$L$251=$D7)*(Data!$M$2:$M$251=$E7),Data!$N$2:$N$251," " ))} -> 12 | G7: 1.0415 | H7: 0.5 | I7: =2*Data!D7 -> 0.31 | J7: {=AVERAGE(IF((Data!$F$2:$F$251=$A7)*(Data!$H$2:$H$251=$B7)*(Data!$K$2:$K$251=$C7)*(Data!$L$2:$L$251=$D7)*(Data!$M$2:$M$251=$E7),Data!$N$2:$N$251," " ))} -> 139.30667 | K7: {=STDEV(IF((Data!$F$2:$F$251=$A7)*(Data!$H$2:$H$251=$B7)*(Data!$K$2:$K$251=$C7)*(Data!$L$2:$L$251=$D7)*(Data!$M$2:$M$251=$E7),Data!$N$2:$N$251," " ))} -> 7.0333775 | L7: =G7*K7/SQRT(F7) -> 2.1146212 | M7: =J7*2% -> 2.7861333 | N7: =2*SQRT(SUMSQ(H7,I7,L7,M7)) -> 7.0937329 | O7: {=AVERAGE(IF((Data!$F$2:$F$251=$A7)*(Data!$H$2:$H$251=$B7)*(Data!$K$2:$K$251=$C7)*(Data!$L$2:$L$251=$D7)*(Data!$M$2:$M$251=$E7),Data!$O$2:$O$251," " ))} -> 140.41342 | P7: {=STDEV(IF((Data!$F$2:$F$251=$A7)*(Data!$H$2:$H$251=$B7)*(Data!$K$2:$K$251=$C7)*(Data!$L$2:$L$251=$D7)*(Data!$M$2:$M$251=$E7),Data!$O$2:$O$251," " ))} -> 5.9196714 | Q7: =G7*P7/SQRT(F7) -> 1.7797797 | R7: =O7*5% -> 7.0206708 | S7: =2*SQRT(SUMSQ(H7,I7,Q7,R7)) -> 14.533208
A8: IN625 | B8: AMMT | C8: 50 | D8: 195 | E8: 800 | F8: {=COUNT(IF((Data!$F$2:$F$251=$A8)*(Data!$H$2:$H$251=$B8)*(Data!$K$2:$K$251=$C8)*(Data!$L$2:$L$251=$D8)*(Data!$M$2:$M$251=$E8),Data!$N$2:$N$251," " ))} -> 4 | G8: 1.1978 | H8: 0.5 | I8: =2*Data!D8 -> 0.31 | J8: {=AVERAGE(IF((Data!$F$2:$F$251=$A8)*(Data!$H$2:$H$251=$B8)*(Data!$K$2:$K$251=$C8)*(Data!$L$2:$L$251=$D8)*(Data!$M$2:$M$251=$E8),Data!$N$2:$N$251," " ))} -> 105.54 | K8: {=STDEV(IF((Data!$F$2:$F$251=$A8)*(Data!$H$2:$H$251=$B8)*(Data!$K$2:$K$251=$C8)*(Data!$L$2:$L$251=$D8)*(Data!$M$2:$M$251=$E8),Data!$N$2:$N$251," " ))} -> 1.9329299 | L8: =G8*K8/SQRT(F8) -> 1.1576317 | M8: =J8*2% -> 2.1108 | N8: =2*SQRT(SUMSQ(H8,I8,L8,M8)) -> 4.9564858 | O8: {=AVERAGE(IF((Data!$F$2:$F$251=$A8)*(Data!$H$2:$H$251=$B8)*(Data!$K$2:$K$251=$C8)*(Data!$L$2:$L$251=$D8)*(Data!$M$2:$M$251=$E8),Data!$O$2:$O$251," " ))} -> 154.263 | P8: {=STDEV(IF((Data!$F$2:$F$251=$A8)*(Data!$H$2:$H$251=$B8)*(Data!$K$2:$K$251=$C8)*(Data!$L$2:$L$251=$D8)*(Data!$M$2:$M$251=$E8),Data!$O$2:$O$251," " ))} -> 4.4536957 | Q8: =G8*P8/SQRT(F8) -> 2.6673184 | R8: =O8*5% -> 7.71315 | S8: =2*SQRT(SUMSQ(H8,I8,Q8,R8)) -> 16.365008
A9: IN625 | B9: AMMT | C9: 80 | D9: 195 | E9: 800 | F9: {=COUNT(IF((Data!$F$2:$F$251=$A9)*(Data!$H$2:$H$251=$B9)*(Data!$K$2:$K$251=$C9)*(Data!$L$2:$L$251=$D9)*(Data!$M$2:$M$251=$E9),Data!$N$2:$N$251," " ))} -> 2 | G9: 1.819 | H9: 0.5 | I9: =2*Data!D9 -> 0.31 | J9: {=AVERAGE(IF((Data!$F$2:$F$251=$A9)*(Data!$H$2:$H$251=$B9)*(Data!$K$2:$K$251=$C9)*(Data!$L$2:$L$251=$D9)*(Data!$M$2:$M$251=$E9),Data!$N$2:$N$251," " ))} -> 142.3135 | K9: {=STDEV(IF((Data!$F$2:$F$251=$A9)*(Data!$H$2:$H$251=$B9)*(Data!$K$2:$K$251=$C9)*(Data!$L$2:$L$251=$D9)*(Data!$M$2:$M$251=$E9),Data!$N$2:$N$251," " ))} -> 4.5969012 | L9: =G9*K9/SQRT(F9) -> 5.9126595 | M9: =J9*2% -> 2.84627 | N9: =2*SQRT(SUMSQ(H9,I9,L9,M9)) -> 13.176782 | O9: {=AVERAGE(IF((Data!$F$2:$F$251=$A9)*(Data!$H$2:$H$251=$B9)*(Data!$K$2:$K$251=$C9)*(Data!$L$2:$L$251=$D9)*(Data!$M$2:$M$251=$E9),Data!$O$2:$O$251," " ))} -> 93.5585 | P9: {=STDEV(IF((Data!$F$2:$F$251=$A9)*(Data!$H$2:$H$251=$B9)*(Data!$K$2:$K$251=$C9)*(Data!$L$2:$L$251=$D9)*(Data!$M$2:$M$251=$E9),Data!$O$2:$O$251," " ))} -> 2.1630396 | Q9: =G9*P9/SQRT(F9) -> 2.7821605 | R9: =O9*5% -> 4.677925 | S9: =2*SQRT(SUMSQ(H9,I9,Q9,R9)) -> 10.948881
A10: IN625 | B10: AMMT | C10: 122 | D10: 195 | E10: 800 | F10: {=COUNT(IF((Data!$F$2:$F$251=$A10)*(Data!$H$2:$H$251=$B10)*(Data!$K$2:$K$251=$C10)*(Data!$L$2:$L$251=$D10)*(Data!$M$2:$M$251=$E10),Data!$N$2:$N$251," " ))} -> 2 | G10: 1.819 | H10: 0.5 | I10: =2*Data!D10 -> 0.31 | J10: {=AVERAGE(IF((Data!$F$2:$F$251=$A10)*(Data!$H$2:$H$251=$B10)*(Data!$K$2:$K$251=$C10)*(Data!$L$2:$L$251=$D10)*(Data!$M$2:$M$251=$E10),Data!$N$2:$N$251," " ))} -> 124.1475 | K10: {=STDEV(IF((Data!$F$2:$F$251=$A10)*(Data!$H$2:$H$251=$B10)*(Data!$K$2:$K$251=$C10)*(Data!$L$2:$L$251=$D10)*(Data!$M$2:$M$251=$E10),Data!$N$2:$N$251," " ))} -> 1.9862629 | L10: =G10*K10/SQRT(F10) -> 2.5547855 | M10: =J10*2% -> 2.48295 | N10: =2*SQRT(SUMSQ(H10,I10,L10,M10)) -> 7.2216535 | O10: {=AVERAGE(IF((Data!$F$2:$F$251=$A10)*(Data!$H$2:$H$251=$B10)*(Data!$K$2:$K$251=$C10)*(Data!$L$2:$L$251=$D10)*(Data!$M$2:$M$251=$E10),Data!$O$2:$O$251," " ))} -> 50.5395 | P10: {=STDEV(IF((Data!$F$2:$F$251=$A10)*(Data!$H$2:$H$251=$B10)*(Data!$K$2:$K$251=$C10)*(Data!$L$2:$L$251=$D10)*(Data!$M$2:$M$251=$E10),Data!$O$2:$O$251," " ))} -> 0.089802561 | Q10: =G10*P10/SQRT(F10) -> 0.1155065 | R10: =O10*5% -> 2.526975 | S10: =2*SQRT(SUMSQ(H10,I10,Q10,R10)) -> 5.1942447
A11: IN625 | B11: AMMT | C11: 144 | D11: 195 | E11: 800 | F11: {=COUNT(IF((Data!$F$2:$F$251=$A11)*(Data!$H$2:$H$251=$B11)*(Data!$K$2:$K$251=$C11)*(Data!$L$2:$L$251=$D11)*(Data!$M$2:$M$251=$E11),Data!$N$2:$N$251," " ))} -> 2 | G11: 1.819 | H11: 0.5 | I11: =2*Data!D11 -> 0.31 | J11: {=AVERAGE(IF((Data!$F$2:$F$251=$A11)*(Data!$H$2:$H$251=$B11)*(Data!$K$2:$K$251=$C11)*(Data!$L$2:$L$251=$D11)*(Data!$M$2:$M$251=$E11),Data!$N$2:$N$251," " ))} -> 121.1545 | K11: {=STDEV(IF((Data!$F$2:$F$251=$A11)*(Data!$H$2:$H$251=$B11)*(Data!$K$2:$K$251=$C11)*(Data!$L$2:$L$251=$D11)*(Data!$M$2:$M$251=$E11),Data!$N$2:$N$251," " ))} -> 3.1544034 | L11: =G11*K11/SQRT(F11) -> 4.0572795 | M11: =J11*2% -> 2.42309 | N11: =2*SQRT(SUMSQ(H11,I11,L11,M11)) -> 9.524491 | O11: {=AVERAGE(IF((Data!$F$2:$F$251=$A11)*(Data!$H$2:$H$251=$B11)*(Data!$K$2:$K$251=$C11)*(Data!$L$2:$L$251=$D11)*(Data!$M$2:$M$251=$E11),Data!$O$2:$O$251," " ))} -> 41.426 | P11: {=STDEV(IF((Data!$F$2:$F$251=$A11)*(Data!$H$2:$H$251=$B11)*(Data!$K$2:$K$251=$C11)*(Data!$L$2:$L$251=$D11)*(Data!$M$2:$M$251=$E11),Data!$O$2:$O$251," " ))} -> 0.72124892 | Q11: =G11*P11/SQRT(F11) -> 0.92769 | R11: =O11*5% -> 2.0713 | S11: =2*SQRT(SUMSQ(H11,I11,Q11,R11)) -> 4.6891332
A12: IN625 | B12: AMMT | C12: 167 | D12: 195 | E12: 800 | F12: {=COUNT(IF((Data!$F$2:$F$251=$A12)*(Data!$H$2:$H$251=$B12)*(Data!$K$2:$K$251=$C12)*(Data!$L$2:$L$251=$D12)*(Data!$M$2:$M$251=$E12),Data!$N$2:$N$251," " ))} -> 4 | G12: 1.1978 | H12: 0.5 | I12: =2*Data!D12 -> 0.31 | J12: {=AVERAGE(IF((Data!$F$2:$F$251=$A12)*(Data!$H$2:$H$251=$B12)*(Data!$K$2:$K$251=$C12)*(Data!$L$2:$L$251=$D12)*(Data!$M$2:$M$251=$E12),Data!$N$2:$N$251," " ))} -> 135.788 | K12: {=STDEV(IF((Data!$F$2:$F$251=$A12)*(Data!$H$2:$H$251=$B12)*(Data!$K$2:$K$251=$C12)*(Data!$L$2:$L$251=$D12)*(Data!$M$2:$M$251=$E12),Data!$N$2:$N$251," " ))} -> 2.6946778 | L12: =G12*K12/SQRT(F12) -> 1.6138426 | M12: =J12*2% -> 2.71576 | N12: =2*SQRT(SUMSQ(H12,I12,L12,M12)) -> 6.4268002 | O12: {=AVERAGE(IF((Data!$F$2:$F$251=$A12)*(Data!$H$2:$H$251=$B12)*(Data!$K$2:$K$251=$C12)*(Data!$L$2:$L$251=$D12)*(Data!$M$2:$M$251=$E12),Data!$O$2:$O$251," " ))} -> 37.29125 | P12: {=STDEV(IF((Data!$F$2:$F$251=$A12)*(Data!$H$2:$H$251=$B12)*(Data!$K$2:$K$251=$C12)*(Data!$L$2:$L$251=$D12)*(Data!$M$2:$M$251=$E12),Data!$O$2:$O$251," " ))} -> 1.2241316 | Q12: =G12*P12/SQRT(F12) -> 0.73313243 | R12: =O12*5% -> 1.8645625 | S12: =2*SQRT(SUMSQ(H12,I12,Q12,R12)) -> 4.1762071
A13: IN625 | B13: AMMT | C13: 211 | D13: 195 | E13: 800 | F13: {=COUNT(IF((Data!$F$2:$F$251=$A13)*(Data!$H$2:$H$251=$B13)*(Data!$K$2:$K$251=$C13)*(Data!$L$2:$L$251=$D13)*(Data!$M$2:$M$251=$E13),Data!$N$2:$N$251," " ))} -> 2 | G13: 1.819 | H13: 0.5 | I13: =2*Data!D13 -> 0.31 | J13: {=AVERAGE(IF((Data!$F$2:$F$251=$A13)*(Data!$H$2:$H$251=$B13)*(Data!$K$2:$K$251=$C13)*(Data!$L$2:$L$251=$D13)*(Data!$M$2:$M$251=$E13),Data!$N$2:$N$251," " ))} -> 154.4225 | K13: {=STDEV(IF((Data!$F$2:$F$251=$A13)*(Data!$H$2:$H$251=$B13)*(Data!$K$2:$K$251=$C13)*(Data!$L$2:$L$251=$D13)*(Data!$M$2:$M$251=$E13),Data!$N$2:$N$251," " ))} -> 2.7937789 | L13: =G13*K13/SQRT(F13) -> 3.5934345 | M13: =J13*2% -> 3.08845 | N13: =2*SQRT(SUMSQ(H13,I13,L13,M13)) -> 9.5493235 | O13: {=AVERAGE(IF((Data!$F$2:$F$251=$A13)*(Data!$H$2:$H$251=$B13)*(Data!$K$2:$K$251=$C13)*(Data!$L$2:$L$251=$D13)*(Data!$M$2:$M$251=$E13),Data!$O$2:$O$251," " ))} -> 31.8025 | P13: {=STDEV(IF((Data!$F$2:$F$251=$A13)*(Data!$H$2:$H$251=$B13)*(Data!$K$2:$K$251=$C13)*(Data!$L$2:$L$251=$D13)*(Data!$M$2:$M$251=$E13),Data!$O$2:$O$251," " ))} -> 1.5323004 | Q13: =G13*P13/SQRT(F13) -> 1.9708865 | R13: =O13*5% -> 1.590125 | S13: =2*SQRT(SUMSQ(H13,I13,Q13,R13)) -> 5.199612
... A71: IN625 | B71: EOS M270 | C71: 322.22 | D71: 195 | E71: 800 | F71: {=COUNT(IF((Data!$F$2:$F$251=$A71)*(Data!$H$2:$H$251=$B71)*(Data!$K$2:$K$251=$C71)*(Data!$L$2:$L$251=$D71)*(Data!$M$2:$M$251=$E71),Data!$N$2:$N$251," " ))} -> 4 | G71: 1.1978 | H71: 0.5 | I71: =2*Data!D71 -> 1.86 | J71: {=AVERAGE(IF((Data!$F$2:$F$251=$A71)*(Data!$H$2:$H$251=$B71)*(Data!$K$2:$K$251=$C71)*(Data!$L$2:$L$251=$D71)*(Data!$M$2:$M$251=$E71),Data!$N$2:$N$251," " ))} -> 189.34725 | K71: {=STDEV(IF((Data!$F$2:$F$251=$A71)*(Data!$H$2:$H$251=$B71)*(Data!$K$2:$K$251=$C71)*(Data!$L$2:$L$251=$D71)*(Data!$M$2:$M$251=$E71),Data!$N$2:$N$251," " ))} -> 5.3499879 | L71: =G71*K71/SQRT(F71) -> 3.2041078 | M71: =J71*2% -> 3.786945 | N71: =2*SQRT(SUMSQ(H71,I71,L71,M71)) -> 10.642718 | O71: {=AVERAGE(IF((Data!$F$2:$F$251=$A71)*(Data!$H$2:$H$251=$B71)*(Data!$K$2:$K$251=$C71)*(Data!$L$2:$L$251=$D71)*(Data!$M$2:$M$251=$E71),Data!$O$2:$O$251," " ))} -> 20.936 | P71: {=STDEV(IF((Data!$F$2:$F$251=$A71)*(Data!$H$2:$H$251=$B71)*(Data!$K$2:$K$251=$C71)*(Data!$L$2:$L$251=$D71)*(Data!$M$2:$M$251=$E71),Data!$O$2:$O$251," " ))} -> 1.523631 | Q71: =G71*P71/SQRT(F71) -> 0.91250259 | R71: =O71*5% -> 1.0468 | S71: =2*SQRT(SUMSQ(H71,I71,Q71,R71)) -> 4.7489162
